Workbook
Name _xlchart.v1.6: Summary!$D$7:$D$13
Name _xlchart.v1.3: Summary!$D$7:$D$13
Name _xlchart.v1.20: Summary!$E$7:$E$14
Name _xlchart.v1.1: Summary!$E$6
Name _xlchart.v1.19: Summary!$E$6
Name _xlchart.v1.14: Summary!$E$7:$E$14
Name _xlchart.v1.16: Summary!$E$6
Name _xlchart.v1.15: Summary!$D$7:$D$13
Name _xlchart.v1.12: Summary!$D$7:$D$13
Name _xlchart.v1.2: Summary!$E$7:$E$14
Name _xlchart.v1.0: Summary!$D$7:$D$13
Name _xlchart.v1.10: Summary!$E$6
Name _xlchart.v1.7: Summary!$E$6
Name _xlchart.v1.5: Summary!$E$7:$E$14
Name _xlchart.v1.11: Summary!$E$7:$E$14
Name _xlchart.v1.9: Summary!$D$7:$D$13
Name _xlchart.v1.13: Summary!$E$6
Name _xlchart.v1.8: Summary!$E$7:$E$14
Name _xlchart.v1.18: Summary!$D$7:$D$13
Name _xlchart.v1.4: Summary!$E$6
Name _xlchart.v1.17: Summary!$E$7:$E$14

Sheet Summary
B1: CLIENT SEO Audit Summary
B2: Introduction The purpose of this audit is to identify any existing problems that may be interfering with how search engines crawl, index and surface content. The site has been assessed for 70 potential issues across the following four pillars: • Crawling • Content • Technical • Local Following a diagnosis of the problem, we have specified how each issue relates to your website and what steps need to be taken to remedy the situation. First Page recognises that it's not always possible to implement all recommendations at once due to technical and resource constraints. To this end, each issue has been assigned a priority weighting ranging from critical (high) to low impact (low). We have also specified which party will be responsible for carrying out the necessary changes. Please note: These recommendations will require further discussion with your technical and/or marketing teams to assess their feasibility. Alternative recommendations that fall outside the scope of this document may also need to be discussed.
B3: Initial Findings & Insights Please refer to the radar chart below for a performance rating across each of the pillars, with 100% being a perfect score.
B5: Initial Findings & Insights: Please refer to the radar chart below for a performance rating across each of the pillars, with 100% being a perfect score.
D6: SEO Pillar | E6: Score
D7: ='X SEO Audit Checklist (AM)'!A4 -> #REF! | E7: ='X SEO Audit Checklist (AM)'!G4 -> #REF!
D8: ='X SEO Audit Checklist (AM)'!A41 -> #REF! | E8: ='X SEO Audit Checklist (AM)'!G41 -> #REF!
D9: ='X SEO Audit Checklist (AM)'!A73 -> #REF! | E9: ='X SEO Audit Checklist (AM)'!G73 -> #REF!
D10: ='X SEO Audit Checklist (AM)'!A93 -> #REF! | E10: ='X SEO Audit Checklist (AM)'!G93 -> #REF!
D11: Tracking | E11: ='X SEO Audit Checklist (AM)'!G98 -> #REF!
D12: SEO Pillar | E12: Score
D13: ='X SEO Audit Checklist (AM)'!A4 -> #REF! | E13: =#REF! -> #REF!
D14: ='X SEO Audit Checklist (AM)'!A41 -> #REF! | E14: ='X SEO Audit Checklist (AM)'!G41 -> #REF!
D15: ='X SEO Audit Checklist (AM)'!A73 -> #REF! | E15: ='X SEO Audit Checklist (AM)'!G73 -> #REF!
D16: ='X SEO Audit Checklist (AM)'!A93 -> #REF! | E16: =#REF! -> #REF!
D17: Tracking | E17: =#REF! -> #REF!
B38: WIP Findings & Insights: Please refer to the radar chart below for a performance rating across each of the pillars, with 100% being a perfect score.

Sheet Keyword Allocation (EN)
A1: Keyword Allocation
D2: Current Position | E2: Ranking URL
A3: Page URL: | D3: =IFERROR(vlookup(B3,SV!$A$1:$C115,2,false),"") | E3: =IFERROR(vlookup(B3,SV!$A$1:$C115,3,false),"")
A4: Old Title: | B4: =IFERROR(__xludf.DUMMYFUNCTION("iferror(IMPORTXML(B3, ""//head/title/text()""),"""")"),"") | D4: =IFERROR(vlookup(B4,SV!$A$1:$C115,2,false),"") | E4: =IFERROR(vlookup(B4,SV!$A$1:$C115,3,false),"")
A5: NEW Title: | D5: =IFERROR(vlookup(B5,SV!$A$1:$C115,2,false),"") | E5: =IFERROR(vlookup(B5,SV!$A$1:$C115,3,false),"")
A6: Keywords: | D6: =IFERROR(vlookup(B6,SV!$A$1:$C115,2,false),"") | E6: =IFERROR(vlookup(B6,SV!$A$1:$C115,3,false),"")
D7: =IFERROR(vlookup(B7,SV!$A$1:$C115,2,false),"") | E7: =IFERROR(vlookup(B7,SV!$A$1:$C115,3,false),"")
D8: =IFERROR(vlookup(B8,SV!$A$1:$C115,2,false),"") | E8: =IFERROR(vlookup(B8,SV!$A$1:$C115,3,false),"")
D9: =IFERROR(vlookup(B9,SV!$A$1:$C115,2,false),"") | E9: =IFERROR(vlookup(B9,SV!$A$1:$C115,3,false),"")
D10: =IFERROR(vlookup(B10,SV!$A$1:$C115,2,false),"") | E10: =IFERROR(vlookup(B10,SV!$A$1:$C115,3,false),"")
D11: =IFERROR(vlookup(B11,SV!$A$1:$C115,2,false),"") | E11: =IFERROR(vlookup(B11,SV!$A$1:$C115,3,false),"")
D12: =IFERROR(vlookup(B12,SV!$A$1:$C115,2,false),"") | E12: =IFERROR(vlookup(B12,SV!$A$1:$C115,3,false),"")
D13: =IFERROR(vlookup(B13,SV!$A$1:$C115,2,false),"") | E13: =IFERROR(vlookup(B13,SV!$A$1:$C115,3,false),"")
D14: =IFERROR(vlookup(B14,SV!$A$1:$C115,2,false),"") | E14: =IFERROR(vlookup(B14,SV!$A$1:$C115,3,false),"")
D15: =IFERROR(vlookup(B15,SV!$A$1:$C115,2,false),"") | E15: =IFERROR(vlookup(B15,SV!$A$1:$C115,3,false),"")
D16: Current Position | E16: Ranking URL
A17: Page URL: | D17: =IFERROR(vlookup(B17,SV!$A$1:$C115,2,false),"") | E17: =IFERROR(vlookup(B17,SV!$A$1:$C115,3,false),"")
A18: Old Title: | B18: =IFERROR(__xludf.DUMMYFUNCTION("iferror(IMPORTXML(B17, ""//head/title/text()""),"""")"),"") | D18: =IFERROR(vlookup(B18,SV!$A$1:$C115,2,false),"") | E18: =IFERROR(vlookup(B18,SV!$A$1:$C115,3,false),"")
A19: NEW Title: | D19: =IFERROR(vlookup(B19,SV!$A$1:$C115,2,false),"") | E19: =IFERROR(vlookup(B19,SV!$A$1:$C115,3,false),"")
A20: Keywords: | D20: =IFERROR(vlookup(B20,SV!$A$1:$C115,2,false),"") | E20: =IFERROR(vlookup(B20,SV!$A$1:$C115,3,false),"")
D21: =IFERROR(vlookup(B21,SV!$A$1:$C115,2,false),"") | E21: =IFERROR(vlookup(B21,SV!$A$1:$C115,3,false),"")
D22: =IFERROR(vlookup(B22,SV!$A$1:$C115,2,false),"") | E22: =IFERROR(vlookup(B22,SV!$A$1:$C115,3,false),"")
D23: =IFERROR(vlookup(B23,SV!$A$1:$C115,2,false),"") | E23: =IFERROR(vlookup(B23,SV!$A$1:$C115,3,false),"")
D24: =IFERROR(vlookup(B24,SV!$A$1:$C115,2,false),"") | E24: =IFERROR(vlookup(B24,SV!$A$1:$C115,3,false),"")
D25: =IFERROR(vlookup(B25,SV!$A$1:$C115,2,false),"") | E25: =IFERROR(vlookup(B25,SV!$A$1:$C115,3,false),"")
D26: =IFERROR(vlookup(B26,SV!$A$1:$C115,2,false),"") | E26: =IFERROR(vlookup(B26,SV!$A$1:$C115,3,false),"")
D27: =IFERROR(vlookup(B27,SV!$A$1:$C115,2,false),"") | E27: =IFERROR(vlookup(B27,SV!$A$1:$C115,3,false),"")
D28: =IFERROR(vlookup(B28,SV!$A$1:$C115,2,false),"") | E28: =IFERROR(vlookup(B28,SV!$A$1:$C115,3,false),"")
D29: =IFERROR(vlookup(B29,SV!$A$1:$C115,2,false),"") | E29: =IFERROR(vlookup(B29,SV!$A$1:$C115,3,false),"")
D30: Current Position | E30: Ranking URL
A31: Page URL: | D31: =IFERROR(vlookup(B31,SV!$A$1:$C115,2,false),"") | E31: =IFERROR(vlookup(B31,SV!$A$1:$C115,3,false),"")
A32: Old Title: | B32: =IFERROR(__xludf.DUMMYFUNCTION("iferror(IMPORTXML(B31, ""//head/title/text()""),"""")"),"") | D32: =IFERROR(vlookup(B32,SV!$A$1:$C115,2,false),"") | E32: =IFERROR(vlookup(B32,SV!$A$1:$C115,3,false),"")
A33: NEW Title: | D33: =IFERROR(vlookup(B33,SV!$A$1:$C115,2,false),"") | E33: =IFERROR(vlookup(B33,SV!$A$1:$C115,3,false),"")
A34: Keywords: | D34: =IFERROR(vlookup(B34,SV!$A$1:$C115,2,false),"") | E34: =IFERROR(vlookup(B34,SV!$A$1:$C115,3,false),"")
D35: =IFERROR(vlookup(B35,SV!$A$1:$C115,2,false),"") | E35: =IFERROR(vlookup(B35,SV!$A$1:$C115,3,false),"")
D36: =IFERROR(vlookup(B36,SV!$A$1:$C115,2,false),"") | E36: =IFERROR(vlookup(B36,SV!$A$1:$C115,3,false),"")
D37: =IFERROR(vlookup(B37,SV!$A$1:$C115,2,false),"") | E37: =IFERROR(vlookup(B37,SV!$A$1:$C115,3,false),"")
D38: =IFERROR(vlookup(B38,SV!$A$1:$C115,2,false),"") | E38: =IFERROR(vlookup(B38,SV!$A$1:$C115,3,false),"")
D39: =IFERROR(vlookup(B39,SV!$A$1:$C115,2,false),"") | E39: =IFERROR(vlookup(B39,SV!$A$1:$C115,3,false),"")
D40: =IFERROR(vlookup(B40,SV!$A$1:$C115,2,false),"") | E40: =IFERROR(vlookup(B40,SV!$A$1:$C115,3,false),"")
...

Sheet SEO Implementation Checklist
C1: SEO and GEO Audit Checklist | E1: Delete Unused Tabs
B2: # | C2: ITEM | D2: Initial Check | E2: Detailed Tab Links / Specific Instructions | F2: Onsite Type | G2: Notes/ Tools
A3: Pre-Check | B3: 1 | C3: Initial SEO Metrics
B4: 1.1 | C4: BENCHMARK REPORT IN SENTR | D4: ✔ | E4: No begin onsite until benchmark report is added by AM
B5: 1.2 | C5: IS DOMAIN/COUNTRY/CMS/CONFIG suitable for achieving SEO goals? | D5: ✔ | E5: Check if domain matches country (GMB + location) and CMS is editable
B6: 1.3 | C6: CMS | D6: WordPress
B7: 1.4 | C7: Domain Authority | D7: 20 | E7: https://moz.com/domain-analysis
B8: 1.5 | C8: Number of Referring Domains | D8: 334 | E8: https://ahrefs.com/backlink-checker
B9: 1.6 | C9: Number of Indexed Pages | D9: 30 | E9: Use site: search in Google. site:example.com
B10: 1.7 | C10: Does the client need a separate Traffic Drop Investigation | D10: NA | E10: AM please create separate task
B11: 2 | C11: Before You Start - Check All Necessary Logins + Setup
B12: 2.1 | C12: All Google Logins: GSC, GTM + GA4 | D12: ✔
B13: 2.2 | C13: Install GA4 | D13: ✔ | E13: https://support.google.com/analytics/answer/1008080?hl=en
B14: 2.3 | C14: Install & Set up GSC | D14: ✔ | E14: https://support.google.com/webmasters/answer/34592?hl=en
B15: 2.4 | C15: GA links to GSC | D15: ✔
B16: 2.5 | C16: GEO Targeting set up? | D16: ✔
B17: 2.6 | C17: CMS access | D17: ✔
B18: 2.7 | C18: Cpanel | D18: NA
B19: 3 | C19: Full Site Backup Before Initial Onsite (Begin Onsite)
B20: 3.1 | C20: Files - All Files Backup (Use FTP/SFTP to download all Files/Folders), Upload to Google Drive | E20: https://wordpress.org/plugins/updraftplus/
B21: 3.2 | C21: Database - All Database Backup (Use phpMyAdmin to generate SQL), Upload to Google Drive | E21: https://wordpress.org/support/article/backing-up-your-database/
B22: 4 | C22: Keyword
B23: 4.1 | C23: Keyword research | D23: ✔ | E23: https://moz.com/learn/seo/what-is-keyword-research
B24: 4.2 | C24: Keyword allocation | D24: ✔ | E24: Define target pages and allocate a cluster of KWs (2 - 10 to each)
B25: 4.3 | C25: Does the client need a separate Keyword Ranking Drop Investigation? | D25: ✔ | E25: 4. Keyword Drop
B26: 4.4 | C26: Prompt research completed | D26: NA | F26: GEO
B27: 4.5 | C27: Prompt allocation to URLs completed | D27: NA | F27: GEO
B28: 5 | C28: Site Architecture - add on new tab after keyword allocation
B29: 5.1 | C29: Can we add a new page?
B30: 5.2 | C30: Can we add a new header menu item under the existing header menu?
B31: 5.3 | C31: Can we add a new submenu item under an existing header menu item?
B32: 5.4 | C32: Can we add an Accordion menu without having a design issue?
B33: 5.5 | C33: Can we add SEO Title, Descriptions and H tags without having a design issue?
B34: 5.6 | C34: Can we add SEO Title, Descriptions and H tags without having a structural issue in the code?
B35: 5.7 | C35: Can we add a new category page?
B36: 5.8 | C36: How do GTM code placements look? Have they been placed under <head> and <body> tags?
B37: 6 | C37: Security
B38: 6.1 | C38: Does the site have a security plugin/firewall active? Up-to-date plugins? | E38: For WP - Wordfence etc, WIX/Shopify fine. Custom - use hosting firewall.
B39: 6.2 | C39: =HYPERLINK("https://transparencyreport.google.com/safe-browsing/search/", "https://transparencyreport.google.com/safe-browsing/search") -> https://transparencyreport.google.com/safe-browsing/search | E39: https://support.google.com/websearch/answer/190597?hl=en
B40: 6.3 | C40: =HYPERLINK("https://sitecheck.sucuri.net/results/","https://sitecheck.sucuri.net/results/") -> https://sitecheck.sucuri.net/results/ | E40: https://support.google.com/webmasters/answer/2721435?hl=en&ref_topic=4596795
...

Sheet SV
A1: Keyword | B1: Position | C1: Google Ranking URL

Sheet Priorities & Status
B1: Item | C1: Detailed Notes | D1: Responsibility | E1: Priority | F1: Require Developer? Exported > True / False Conditional Coloring | G1: Completed? (AM & Client Use) | H1: SEO / GEO Item?
A2: =IFERROR(__xludf.DUMMYFUNCTION("query('SEO Implementation Checklist'!B3:E1023, ""SELECT B, C WHERE B is not null and D = '✖'"", 0)"),35.6) -> 35.6 | B2: =IFERROR(__xludf.DUMMYFUNCTION("""COMPUTED_VALUE"""),"TL;DR / summary blocks at top of articles?") -> TL;DR / summary blocks at top of articles? | C2: 35. Content Optimisation for GEO | D2: First Page & Client | E2: MEDIUM
A3: =IFERROR(__xludf.DUMMYFUNCTION("""COMPUTED_VALUE"""),23.1) -> 23.1 | B3: =IFERROR(__xludf.DUMMYFUNCTION("""COMPUTED_VALUE"""),"Is there JSON-LD for in header for: organization:name,url,logo,sameAs") -> Is there JSON-LD for in header for: organization:name,url,logo,sameAs | C3: 23. Rich Snippets | D3: First Page & Client | E3: MEDIUM
A4: =IFERROR(__xludf.DUMMYFUNCTION("""COMPUTED_VALUE"""),23.70000000000001) -> 23.7 | B4: =IFERROR(__xludf.DUMMYFUNCTION("""COMPUTED_VALUE"""),"Is there FAQ schema? (Optional - If FAQ is listed on pages, use ChatGPT to create FAQ schema with a screencap)") -> Is there FAQ schema? (Optional - If FAQ is listed on pages, use ChatGPT to create FAQ schema with a screencap) | C4: 23. Rich Snippets | D4: First Page & Client | E4: MEDIUM
C5: =if(A5="", "", vlookup(A5, 'SEO Implementation Checklist'!$B:$E,4, false))
C6: =if(A6="", "", vlookup(A6, 'SEO Implementation Checklist'!$B:$E,4, false))
C7: =if(A7="", "", vlookup(A7, 'SEO Implementation Checklist'!$B:$E,4, false))
C8: =if(A8="", "", vlookup(A8, 'SEO Implementation Checklist'!$B:$E,4, false))
C9: =if(A9="", "", vlookup(A9, 'SEO Implementation Checklist'!$B:$E,4, false))
C10: =if(A10="", "", vlookup(A10, 'SEO Implementation Checklist'!$B:$E,4, false))
C11: =if(A11="", "", vlookup(A11, 'SEO Implementation Checklist'!$B:$E,4, false))
C12: =if(A12="", "", vlookup(A12, 'SEO Implementation Checklist'!$B:$E,4, false))
C13: =if(A13="", "", vlookup(A13, 'SEO Implementation Checklist'!$B:$E,4, false))
C14: =if(A14="", "", vlookup(A14, 'SEO Implementation Checklist'!$B:$E,4, false))
C15: =if(A15="", "", vlookup(A15, 'SEO Implementation Checklist'!$B:$E,4, false))
C16: =if(A16="", "", vlookup(A16, 'SEO Implementation Checklist'!$B:$E,4, false))
... C21: =if(A21="", "", vlookup(A21, 'SEO Implementation Checklist'!$B:$E,4, false))
C75: =if(A75="", "", vlookup(A75+0.01, 'SEO Implementation Checklist'!$B:$E, counta('SEO Implementation Checklist'!$B$2:$E$2), true)) | D75: Client | E75: N/A | F75: FALSE | G75: FALSE
C76: =if(A76="", "", vlookup(A76+0.01, 'SEO Implementation Checklist'!$B:$E, counta('SEO Implementation Checklist'!$B$2:$E$2), true)) | D76: Client | E76: N/A | F76: FALSE | G76: FALSE
C77: =if(A77="", "", vlookup(A77+0.01, 'SEO Implementation Checklist'!$B:$E, counta('SEO Implementation Checklist'!$B$2:$E$2), true)) | D77: Client | E77: N/A | F77: FALSE | G77: FALSE
C78: =if(A78="", "", vlookup(A78+0.01, 'SEO Implementation Checklist'!$B:$E, counta('SEO Implementation Checklist'!$B$2:$E$2), true)) | D78: Client | E78: N/A | F78: FALSE | G78: FALSE
C79: =if(A79="", "", vlookup(A79+0.01, 'SEO Implementation Checklist'!$B:$E, counta('SEO Implementation Checklist'!$B$2:$E$2), true)) | D79: Client | E79: N/A | F79: FALSE | G79: FALSE
C80: =if(A80="", "", vlookup(A80+0.01, 'SEO Implementation Checklist'!$B:$E, counta('SEO Implementation Checklist'!$B$2:$E$2), true)) | D80: Client | E80: N/A | F80: FALSE | G80: FALSE
C81: =if(A81="", "", vlookup(A81+0.01, 'SEO Implementation Checklist'!$B:$E, counta('SEO Implementation Checklist'!$B$2:$E$2), true)) | D81: Client | E81: N/A | F81: FALSE | G81: FALSE
C82: =if(A82="", "", vlookup(A82+0.01, 'SEO Implementation Checklist'!$B:$E, counta('SEO Implementation Checklist'!$B$2:$E$2), true)) | D82: Client | E82: N/A | F82: FALSE | G82: FALSE
C83: =if(A83="", "", vlookup(A83+0.01, 'SEO Implementation Checklist'!$B:$E, counta('SEO Implementation Checklist'!$B$2:$E$2), true)) | D83: Client | E83: N/A | F83: FALSE | G83: FALSE
C84: =if(A84="", "", vlookup(A84+0.01, 'SEO Implementation Checklist'!$B:$E, counta('SEO Implementation Checklist'!$B$2:$E$2), true)) | D84: Client | E84: N/A | F84: FALSE | G84: FALSE
C85: =if(A85="", "", vlookup(A85+0.01, 'SEO Implementation Checklist'!$B:$E, counta('SEO Implementation Checklist'!$B$2:$E$2), true)) | D85: Client | E85: N/A | F85: FALSE | G85: FALSE
C86: =if(A86="", "", vlookup(A86+0.01, 'SEO Implementation Checklist'!$B:$E, counta('SEO Implementation Checklist'!$B$2:$E$2), true)) | D86: Client | E86: N/A | F86: FALSE | G86: FALSE
... C142: =if(A142="", "", vlookup(A142+0.01, 'SEO Implementation Checklist'!$B:$E, counta('SEO Implementation Checklist'!$B$2:$E$2), true)) | D142: Client | E142: N/A | F142: FALSE | G142: FALSE
C143: =if(A143="", "", vlookup(A143+0.01, 'SEO Implementation Checklist'!$B:$E, counta('SEO Implementation Checklist'!$B$2:$E$2), true)) | D143: Client | E143: N/A
C144: =if(A144="", "", vlookup(A144+0.01, 'SEO Implementation Checklist'!$B:$E, counta('SEO Implementation Checklist'!$B$2:$E$2), true)) | D144: Client | E144: N/A
C145: =if(A145="", "", vlookup(A145+0.01, 'SEO Implementation Checklist'!$B:$E, counta('SEO Implementation Checklist'!$B$2:$E$2), true)) | D145: Client | E145: N/A
C146: =if(A146="", "", vlookup(A146+0.01, 'SEO Implementation Checklist'!$B:$E, counta('SEO Implementation Checklist'!$B$2:$E$2), true)) | D146: Client | E146: N/A
C147: =if(A147="", "", vlookup(A147+0.01, 'SEO Implementation Checklist'!$B:$E, counta('SEO Implementation Checklist'!$B$2:$E$2), true)) | D147: Client | E147: N/A
C148: =if(A148="", "", vlookup(A148+0.01, 'SEO Implementation Checklist'!$B:$E, counta('SEO Implementation Checklist'!$B$2:$E$2), true)) | D148: Client | E148: N/A
C149: =if(A149="", "", vlookup(A149+0.01, 'SEO Implementation Checklist'!$B:$E, counta('SEO Implementation Checklist'!$B$2:$E$2), true)) | D149: Client | E149: N/A
C150: =if(A150="", "", vlookup(A150+0.01, 'SEO Implementation Checklist'!$B:$E, counta('SEO Implementation Checklist'!$B$2:$E$2), true)) | D150: Client | E150: N/A
C151: =if(A151="", "", vlookup(A151+0.01, 'SEO Implementation Checklist'!$B:$E, counta('SEO Implementation Checklist'!$B$2:$E$2), true)) | D151: Client | E151: N/A
C152: =if(A152="", "", vlookup(A152+0.01, 'SEO Implementation Checklist'!$B:$E, counta('SEO Implementation Checklist'!$B$2:$E$2), true)) | D152: Client | E152: N/A
...

Sheet 10. Robots.txt
A1: Implementation Checklist | B1: What Is It? Why Is It Important? General Recommendation
A2: Priorities & Status
A3: Put new robots.txt here
A4: Rules To Add (Tested) / Remove | B4: URL Example | C4: Remarks | D4: Screenshots (If have)

Sheet 7. GSC Checks
A1: Implementation Checklist
A2: Priorities & Status
A3: Address | B3: Issues | C3: Instructions (If have) | D3: Keywords

Sheet 9. Implement HTTPS Protocol
A1: Implementation Checklist | B1: What Is It? Why Is It Important? General Recommendation
A2: Priorities & Status
A3: Source | B3: Destination | C3: Anchor Text | D3: Issues | E3: Screenshots (If have) | F3: Specific Instructions (If have)

Sheet 11. Sitemap
A1: Implementation Checklist | B1: What Is It? Why Is It Important? General Recommendation
A2: Priorities & Status
A3: Sitemaps | B3: URLs Example | C3: Instructions | D3: Screenshots (If Applicable)

Sheet 12. Robots meta tags
A1: Implementation Checklist | B1: What Is It? Why Is It Important? General Recommendations
A2: Priorities & Status
A3: Address | B3: Issues | C3: Screenshots (If have)

Sheet 13. Canonical tag
A1: Implementation Checklist | B1: What Is It? Why Is It Important? General Recommendation
A2: Priorities & Status
A3: Address | B3: Issues | C3: Canonical Link Element | D3: Instructions | E3: Screenshots (If have)

Sheet 17.1 Page titles - Missing
A1: Implementation Checklist | B1: Prompt | C1: What Is It? Why Is It Important? General Recommendation
A2: Priorities & Status | B2: write Chinese SEO optimized page titles within 580 pixels for the following URLs, titles must end with - {brand name}:
A3: Address | B3: New Title | C3: Remarks

Sheet 17.2 Page titles - Duplicate
A1: Implementation Checklist | B1: What Is It? Why Is It Important? General Recommendation | C1: Prompt
A2: Priorities & Status | C2: write Chinese SEO optimized page titles within 580 pixels for the following URLs, titles must end with - {brand name}:
A3: Address | B3: Titles | C3: New Title | D3: Instructions (If have)

Sheet 17.3 Page Titles - Too Long
A1: Implementation Checklist | B1: What Is It? Why Is It Important? General Recommendation
A2: Priorities & Status
A3: Address | B3: Title - 1 | C3: Pixel Width ( max 580 pixels) | D3: Revised Title

Sheet 17.4 Page Titles - Multiple
A1: Implementation Checklist | B1: What Is It? Why Is It Important? General Recommendation
A2: Priorities & Status
A3: Address | B3: Title - 1 | C3: Title - 2 | D3: Instructions

Sheet 18. Descriptions - Missing
A1: Implementation Checklist | B1: What Is It? Why Is It Important? General Recommendation
A2: Priorities & Status
A3: Address | B3: Remarks

Sheet 18.2 Descriptions - Duplicate
A1: Implementation Checklist | B1: What Is It? Why Is It Important? General Recommendation
A2: Priorities & Status
A3: Address | B3: Meta Description

Sheet 18.3 Descriptions - Too Long
A1: Implementation Checklist | B1: What Is It? Why Is It Important? General Recommendation | C1: SF > Config > Spider > Preferences > 880 pixels (mobile max)
A2: Priorities & Status
A3: Address | B3: Meta Description | C3: Pixel Width

Sheet 19.1 H1 - Missing
A1: Implementation Checklist | B1: What Is It? Why Is It Important? General Recommendation
A2: Priorities & Status
A3: Address | B3: Remarks

Sheet 19.2 H1 - Duplicate
A1: Implementation Checklist | B1: What Is It? Why Is It Important? General Recommendation
A2: Priorities & Status
A3: Address | B3: H1 | C3: Instructions

Sheet 19.3 H1 - Multiple
A1: Implementation Checklist | B1: What Is It? Why Is It Important? General Recommendation
A2: Priorities & Status
A3: Address | B3: H1-1 | C3: H1-2

Sheet 20.1 Image - Alt Text Missing
A1: Implementation Checklist | B1: What Is It? Why Is It Important? General Recommendation
A2: Priorities & Status
A3: Source | B3: Destination | C3: Example Screenshots (If Applicable)

Sheet 20.2 Image - Oversize
A1: Implementation Checklist | B1: What Is It? Why Is It Important? General Recommendation | C1: Bulk Export > Images > copy from excel, Images over 100KB, Only put non-webp images here
A2: Priorities & Status
A3: Source | B3: Destination | C3: Size (Bytes)

Sheet 21.1 Duplicate content - Extern
A1: Implementation Checklist | B1: What Is It? Why Is It Important? General Recommendation
A2: Priorities & Status
A3: Address | B3: Issues | C3: Instructions | D3: Screenshots (If have)
C4: If the website contains an above-average amount of duplicate content. You may want to either remove the duplicate content so it appears on only one of your pages, or modify the content on the various pages to ensure that each page is unique.

Sheet 21.2 Duplicate content - Intern
A1: Implementation Checklist | B1: What Is It? Why Is It Important? General Recommendation
A2: Priorities & Status
A3: Address | B3: Issues | C3: Instructions | D3: Screenshots (If have)

Sheet 22 Content suggestions (SEO)
A1: Implementation Checklist | B1: What Is It? Why Is It Important? General Recommendation
A2: Priorities & Status
A3: Address | B3: Issues | C3: Instructions | D3: Screenshots (If Have)

Sheet 34. AI Visibility Audit
A1: Implementation Checklist | B1: What Is It? Why Is It Important? General Recommendation
A2: Priorities & Status
A3: Address | B3: Issues | C3: Instructions | D3: Screenshots (If Have)

Sheet 33. AI Crawler Directives (GEO)
A1: Implementation Checklist | B1: What Is It? Why Is It Important? General Recommendation
A2: Priorities & Status
A3: Issue | B3: llms.txt example | C3: Instructions

Sheet 35. Content Optimisation for GE
A1: Implementation Checklist | B1: What Is It? Why Is It Important? General Recommendation
A2: Priorities & Status
A3: Address | B3: Instructions | C3: Screenshots (If Have)
A4: Blog Pages | B4: New blog content for GEO should contain Table of Content and TL;DR section for AI search engine to extract the quick answers. | C4: Example from First Page HK articles : https://www.firstpage.hk/resources/content/ai-strategy-guide-from-seo-to-geo-when-ai-overviews-steal-34-of-your-clicks/
A5: Blog Pages | B5: FAQ sections should be added in blogs to answer the quick questions to increase opportunity to be cited in AI overview. FAQ schema is required for each questions in the blog.

Sheet 36. Technical GEO
A1: Implementation Checklist | B1: What Is It? Why Is It Important? General Recommendation
A2: Priorities & Status
A3: Address | B3: Issues | C3: Instructions | D3: Screenshots (If Have)

Sheet 23. Rich Snippets (GEO)
A1: Implementation Checklist | B1: What Is It? Why Is It Important? General Recommendation | G1: One example for each Schema Type, target pages AM plz create separate task
A2: Priorities & Status
A3: Page | B3: URL | C3: Schema type | D3: Current status | E3: CURRENT schema code (live) | F3: Issues / why change | G3: AMENDED / recommended schema code | H3: Wix implementation notes
H4: Wix SEO Settings inject a basic LocalBusiness. To replace/extend, use Settings > Custom Code (header, all pages) OR a Velo page code block. Fill <image>, <logo>, sameAs handles, and REAL reviewCount before publishing. Verify geo coordinates.
H5: Replace via Custom Code. Only keep SearchAction if the Wix site search URL pattern matches; otherwise drop potentialAction.
H6: Add via Custom Code on /price-list. Mirrors the visible pricing — update if package inclusions change. Consider modelling each package as a Product instead if you want star ratings per package.
H7: Custom Code, page-scoped.
H8: Custom Code on /giveaway-gift. Confirm exact per-item prices with client (page prices are approximate). Add product images to each Product for richer results.
H9: Custom Code, page-scoped.
H10: Custom Code on /services2.
H12: Custom Code, page-scoped.
H13: Custom Code on /new.
H14: Custom Code on /new. Steps mirror the on-page 1-4 booking list.
H16: Custom Code, page-scoped.

Sheet 24. Internal linking
A1: Implementation Checklist | B1: What Is It? Why Is It Important? General Recommendation | D1: GSC > Top Linked Pages - Internally > Any Outdated Links Detected
A2: Priorities & Status
A3: Entry Points / Address | B3: Instructions | C3: Anchor Text | D3: Screenshots (If have) | E3: Destination

Sheet 24.6 Redirect Chains
A1: Implementation Checklist | B1: What Is It? Why Is It Important? General Recommendation
A2: Priorities & Status
A3: Address | B3: Destination | C3: Anchor Text | D3: Screenshots (If have)

Sheet 24.7 Orphan URLs
A1: Implementation Checklist | B1: What Is It? Why Is It Important? General Recommendation
A2: Priorities & Status
A3: Address | B3: Located Sitemap | C3: Instruction | D3: Screenshots (If have)

Sheet 24.8 Broken Internal Links
A1: Implementation Checklist | B1: What Is It? Why Is It Important? General Recommendation
A2: Priorities & Status
A3: Address | B3: Broken Link URL | C3: Instruction / Anchor Text | D3: Screenshots (If have)

Sheet 25. Crawling Issues
A1: Implementation Checklist | B1: What Is It? Why Is It Important? General Recommendation
A2: Priorities & Status
A3: Address | B3: Issues | C3: Screenshots (If have) | D3: Instructions

Sheet 26.1 URL best practices
A1: Implementation Checklist | B1: What Is It? Why Is It Important? General Recommendation
A2: Priorities & Status
A3: Address | B3: Issues | C3: Recommendations | D3: Screenshots (If have)

Sheet 26.2 Parameters
A1: Implementation Checklist | B1: What Is It? Why Is It Important? General Recommendation
A2: Priorities & Status
A3: Address | B3: Recommendations | C3: Screenshots (If have)

Sheet 26.3 Underscores
A1: Implementation Checklist | B1: What Is It? Why Is It Important? General Recommendation
A2: Priorities & Status
A3: Address | B3: Recommendations | C3: Screenshots (If have)

Sheet 26.4 Uppercase
A1: Implementation Checklist | B1: What Is It? Why Is It Important? General Recommendation
A2: Priorities & Status
A3: Address | B3: Recommendations | C3: Screenshots (If have)

Sheet 26.5 Multiple Slashes
A1: Implementation Checklist | B1: What Is It? Why Is It Important? General Recommendation
A2: Priorities & Status
A3: Address | B3: Recommendations | C3: Screenshots (If have)

Sheet 27.1 404s
A1: Implementation Checklist | B1: What Is It? Why Is It Important? General Recommendation
A2: Priorities & Status
A3: Address GSC / SF | B3: SF Entry Points | C3: Screenshots (If Require) | D3: Instructions

Sheet 27.2 5xx
A1: Implementation Checklist | B1: What Is It? Why Is It Important? General Recommendation
A2: Priorities & Status
A3: Address | B3: Recommendations | C3: Screenshots (If Have

Sheet 27.3 302s
A1: Implementation Checklist | B1: What Is It? Why Is It Important? General Recommendation
A2: Priorities & Status
A3: Initial Redirect URL | B3: Final Destination URL | C3: Screenshots | D3: Instructions

Sheet 27.5 Competitor 404s
A1: Implementation Checklist
A2: Priorities & Status
A3: Address | B3: Screenshots

Sheet 28. Page speed
A1: Implementation Checklist | B1: What Is It? Why Is It Important? General Recommendation | J1: Homepage Pagespeed Link | L1: GTMetrix Link
A2: Priorities & Status
A3: Address | B3: Performance Score | C3: Speed Index Time (ms) - 1000ms = 1 s | D3: Eliminate Render-Blocking Resources Savings (ms) | E3: Defer Offscreen Images Savings (ms) | F3: Efficiently Encode Images Savings (ms) | G3: Properly Size Images Savings (ms) | H3: Minify CSS Savings (ms) | I3: Minify JavaScript Savings (ms) | J3: Reduce Unused CSS Savings (ms) | K3: Reduce Unused JavaScript Savings (ms) | L3: Serve Images in Next-Gen Savings (ms) | M3: Enable Text Compression Savings (ms)

Sheet 28.4 CWV
A1: Implementation Checklist | B1: What Is It? Why Is It Important? General Recommendation | D1: To provide a good user experience, sites should strive to have Largest Contentful Paint of 2.5 seconds or less. To provide a good user experience, sites should strive to have a CLS score of 0.1 or less To provide a good user experience, sites should strive to have a FID of 100 ms or less
A2: Priorities & Status
A3: Example URL | B3: Group population | C3: Group LCP | D3: Group CLS | E3: Group FID / INP (Use TBT) | F3: URLs in the report are grouped into pages that have a similar user experience. It is assumed that these groups have a common framework and the reasons for any poor behavior of the group will likely be caused by the same underlying reasons.

Sheet 29. Local Search
A1: Implementation Checklist | B1: What Is It? Why Is It Important? General Recommendation
A2: Priorities & Status
A3: Address | B3: Screenshots | C3: Instructions

Sheet 31. Backlink profile
A1: Implementation Checklist | B1: What Is It? Why Is It Important? General Recommendation
A2: Priorities & Status
A3: Address | B3: Issues | C3: Screenshots (If have)

Sheet ItemsSection
A1: 1.1
A2: 1.2
A3: 1.3
A4: 1.4
A5: 1.5
A6: 1.6
A7: 2.1
A8: 2.2
A9: 2.3
A10: 2.4
A11: 2.5
A12: 2.5
... A109: 17.9
A110: 17.10
A111: 18.1
A112: 18.3
A113: 18.4
A114: 19.1
A115: 19.2
A116: 19.4
A117: 19.5
A118: 19.6
A119: 19.7
A120: 19.8
A121: 19.9
A122: 19.1
... A137: 22.9
A138: 22.10
A139: 22.11
A140: 23.1
A141: 23.2
A142: 23.3
A143: 23.4
A144: 23.5
A145: 23.6
A146: 23.7
A147: 23.8
A148: 23.9
A149: 23.1
A150: 23.11
...

Sheet Additions  Removals
A1: Item | B1: Section | C1: Page | D1: Add/Remove | E1: Reason/Reference
A2: Are any images in excess of 100kb? | B2: Site Speed | D2: ADD
A3: Is a CDN in use? | B3: Site Speed | D3: ADD
A4: Social Section | B4: Social Section | D4: ADD
A5: Add value prop around why someone should create an account | B5: Usability Experience Checks | C5: Conversion | D5: ADD
A6: Allow checkout as guest | B6: Usability Experience Checks | C6: Conversion | D6: ADD
A7: Allow users to continue on another device by emailing or saving for later | B7: Usability Experience Checks | C7: Conversion | D7: ADD
A8: Allow users to update their carts (change quantity with steppers, remove) | B8: Usability Experience Checks | C8: Conversion | D8: ADD
A9: Don't redirect into checkout after adding to card | B9: Usability Experience Checks | C9: Conversion | D9: ADD
A10: Have descriptive CTAs | B10: Usability Experience Checks | C10: Conversion | D10: ADD
A11: Let users sign up/sign in with social | B11: Usability Experience Checks | C11: Conversion | D11: ADD
A12: Limit your exit points during the conversion flow | B12: Usability Experience Checks | C12: Conversion | D12: ADD
A13: Reiterate value prop (typically free shipping) in the cart | B13: Usability Experience Checks | C13: Conversion | D13: ADD
A14: Use pagination or a progress bar if more than 2 steps in conversion flow | B14: Usability Experience Checks | C14: Conversion | D14: ADD
A15: Don't use dropdowns for inputs with < 4 options, instead opt for buttons | B15: Usability Experience Checks | C15: Form Optimisation | D15: ADD
A16: Reduce number of fields: A) Remove optional fields, B) Use full name instead of first/last C) Hide company and address line 2, D) Check billing as shipping by default | B16: Usability Experience Checks | C16: Form Optimisation | D16: ADD
... A50: Make sure product descriptions are readable | B50: Usability Experience Checks | C50: Product | D50: ADD
A51: Is there any duplicate content externally? | B51: Content | D51: ADD
A52: Is there any duplicate content internally? | B52: Content | D52: ADD
A53: X-Robots | B53: Technical | D53: ADD
A54: Backlinks | B54: Technical | D54: ADD
A55: Break speed into sections | B55: Linking | D55: ADD
